Workbook

Sheet Lisez-moi
B2: Rubrique | C2: Contenu
B3: Objet | C3: Base de données du mémoire MS MQDE : transmission des prix alimentaires mondiaux à l'inflation dans les 8 pays de l'UEMOA. Panel mensuel 2000-01 à 2026-09.
B4: Origine | C4: Fusion du classeur Base_donnees_memoire_UEMOA_v2 et du fichier MQDE_UEMOA_base_donnees_v1, mise au format GSA (onglets Source et Data, noms de séries du modèle).
B5: État | C5: Les séries temporelles sont vides : seules les caractéristiques par pays (onglet Pays) et les valeurs de contrôle (onglet Controle) sont renseignées.
B7: Collecte, étape 1 | C7: Onglet Monde : coller fao_food et les sous-indices FAO (un CSV), oil_usd et les prix par produit (Pink Sheet), eur_usd (BCE), gscpi (Fed de New York).
B8: Collecte, étape 2 | C8: Onglets pays (BEN, BFA, CIV, GNB, MLI, NER, SEN, TGO) : coller cpi_all et cpi_food depuis FAOSTAT, un pays par onglet.
B9: Collecte, étape 3 | C9: Onglet Suivi : vérifier la ligne « Baseline prête à lancer ». Le code peut alors tourner sur l'onglet Data.
B10: Collecte, étape 4 | C10: Ensuite seulement : cpi_all_alt et cpi_food_alt (recoupement), onglet Annuel, bceao_import_food, rain_anom.
B12: Où coller | C12: Cellules blanches des onglets Monde, des onglets pays et de l'onglet Annuel. Le détail de chaque série (source, fichier, lien) est dans l'onglet Source.
B13: Couleurs | C13: Blanc : à coller. Turquoise clair : formule, ne pas écraser. Gris clair : valeur pré-remplie.
B14: Format | C14: Date en texte AAAA-MM (AAAA dans l'onglet Annuel). Indices et prix en niveau, bruts : aucune variation calculée à la main. Vérifier le séparateur décimal au collage.
B15: Exemple fictif de ligne | C15: Onglet SEN : Date = 2024-03 ; cpi_all = 128,4 ; cpi_food = 141,7. Onglet Monde : Date = 2024-03 ; fao_food = 118,9 ; oil_usd = 84,7 ; eur_usd = 1,087.
... B26: Vigilance 4 | C26: Onglet Controle : l'alignement des dates des valeurs BCEAO reste à confirmer ; les inflations par pays viennent de l'autre fichier et n'ont pas été vérifiées.

Sheet Source
B2: Nom de la série | C2: Fréquence | D2: Type de couverture | E2: Couverture | F2: Source | G2: Unité | H2: Priorité | I2: Onglet | J2: Mode de remplissage | K2: Fichier / série à prendre | L2: Lien | M2: Source de secours | N2: Rôle dans le modèle | O2: Vérification de la source | P2: Statut | Q2: Remarque
B3: cpi_all | C3: mensuelle | D3: Pays | E3: Pays zone UMOA | F3: FAOSTAT, Consumer Price Indices (origine BCEAO / instituts nationaux) | G3: Indice, 2015 = 100 | H3: P0 | I3: Onglets pays | J3: À coller | K3: « General CPI », 8 pays, tous les mois depuis 2000-01, avec les flags | L3: https://data.apps.fao.org/catalog/dataset/941c71b7-137c-49a1-a128-3d71fb24a1de | M3: FMI, CPI ; Banque mondiale ; BCEAO EDEN | N3: Variable dépendante (inflation totale) | O3: Page ouverte le 02/10/2026 | P3: À collecter | Q3: Série annoncée jusqu'à 2025-06. FAOSTAT comble les trous par estimation : reporter les flags dans quality_flag. IHPC rebasé en janvier 2025.
B4: cpi_food | C4: mensuelle | D4: Pays | E4: Pays zone UMOA | F4: FAOSTAT, Consumer Price Indices (origine BCEAO / instituts nationaux) | G4: Indice, 2015 = 100 | H4: P0 | I4: Onglets pays | J4: À coller | K4: « Food CPI », même extraction que cpi_all | L4: https://data.apps.fao.org/catalog/dataset/941c71b7-137c-49a1-a128-3d71fb24a1de | M4: FMI, CPI détaillé ; Banque mondiale ; BCEAO EDEN | N4: Variable dépendante (inflation alimentaire) | O4: Page ouverte le 02/10/2026 | P4: À collecter | Q4: Mêmes limites que cpi_all. Coller l'indice en niveau, jamais un taux d'inflation.
B5: fao_food | C5: mensuelle | D5: Monde | E5: Monde | F5: FAO, Food Price Index (nominal) | G5: Indice, 2014-2016 = 100 | H5: P0 | I5: Monde | J5: À coller | K5: « CSV: Nominal indices (monthly, 1990 onwards) », colonne Food Price Index | L5: https://www.fao.org/worldfoodsituation/foodpricesindex/en/ | M5: FMI, PCPS | N5: Choc principal | O5: Page ouverte le 02/10/2026 | P5: À collecter | Q5: Indice en dollars. Dernier point publié lors de la vérification : août 2026.
B6: oil_usd | C6: mensuelle | D6: Monde | E6: Monde | F6: Banque mondiale, Pink Sheet | G6: USD par baril | H6: P0 | I6: Monde | J6: À coller | K6: CMO-Historical-Data-Monthly.xlsx, feuille Monthly Prices, « Crude oil, Brent » | L6: https://thedocs.worldbank.org/en/doc/18675f1d1639c7a34d463f59263ba0a2-0050012025/related/CMO-Historical-Data-Monthly.xlsx | M6: FMI, PCPS ; bulletin BCEAO | N6: Contrôle (énergie) | O6: Lien relevé ; contenu de mémoire | P6: À collecter | Q6: Garder le Brent sur toute la période. Le bulletin BCEAO publie une moyenne WTI et Brent, non comparable terme à terme.
B7: usd_xof | C7: mensuelle | D7: Zone | E7: Zone UMOA | F7: Calcul : parité FCFA/EUR divisée par eur_usd | G7: FCFA pour 1 USD | H7: P0 | I7: Monde | J7: Formule | K7: Aucun téléchargement | M7: Bulletin BCEAO ; FMI, Exchange Rates | N7: Contrôle (change) ; conversion du choc en FCFA | O7: Calcul | P7: Sans objet | Q7: Découle de la parité fixe. Une série directe (BCEAO, FMI) peut remplacer la formule : écraser alors la colonne.
B8: eur_usd | C8: mensuelle | D8: Monde | E8: Monde | F8: BCE, Data Portal | G8: USD pour 1 EUR, moyenne du mois | H8: P0 | I8: Monde | J8: À coller | K8: Série EXR.M.USD.EUR.SP00.A | L8: https://data.ecb.europa.eu/ | M8: Banque de France ; FRED | N8: Sert à calculer usd_xof | O8: De mémoire, à vérifier | P8: À collecter | Q8: Prendre la moyenne mensuelle, pas la fin de mois.
B9: fao_cereals | C9: mensuelle | D9: Monde | E9: Monde | F9: FAO, Food Price Index | G9: Indice, 2014-2016 = 100 | H9: P1 | I9: Monde | J9: À coller | K9: Même CSV que fao_food, colonne Cereals | L9: https://www.fao.org/worldfoodsituation/foodpricesindex/en/ | M9: FMI, PCPS | N9: Choc par famille de produits | O9: Page ouverte le 02/10/2026 | P9: À collecter | Q9: Mélange blé, maïs et riz : pour le riz seul, utiliser rice_thai.
B10: fao_oils | C10: mensuelle | D10: Monde | E10: Monde | F10: FAO, Food Price Index | G10: Indice, 2014-2016 = 100 | H10: P1 | I10: Monde | J10: À coller | K10: Même CSV, colonne Vegetable Oils | L10: https://www.fao.org/worldfoodsituation/foodpricesindex/en/ | M10: FMI, PCPS | N10: Choc par famille ; composante de import_food_idx | O10: Page ouverte le 02/10/2026 | P10: À collecter
B11: fao_sugar | C11: mensuelle | D11: Monde | E11: Monde | F11: FAO, Food Price Index | G11: Indice, 2014-2016 = 100 | H11: P1 | I11: Monde | J11: À coller | K11: Même CSV, colonne Sugar | L11: https://www.fao.org/worldfoodsituation/foodpricesindex/en/ | M11: FMI, PCPS | N11: Choc par famille de produits | O11: Page ouverte le 02/10/2026 | P11: À collecter
B12: fao_dairy | C12: mensuelle | D12: Monde | E12: Monde | F12: FAO, Food Price Index | G12: Indice, 2014-2016 = 100 | H12: P1 | I12: Monde | J12: À coller | K12: Même CSV, colonne Dairy | L12: https://www.fao.org/worldfoodsituation/foodpricesindex/en/ | M12: FMI, PCPS | N12: Composante de import_food_idx | O12: Page ouverte le 02/10/2026 | P12: À collecter
B13: fao_meat | C13: mensuelle | D13: Monde | E13: Monde | F13: FAO, Food Price Index | G13: Indice, 2014-2016 = 100 | H13: P2 | I13: Monde | J13: À coller | K13: Même CSV, colonne Meat | L13: https://www.fao.org/worldfoodsituation/foodpricesindex/en/ | M13: FMI, PCPS | N13: Complément | O13: Page ouverte le 02/10/2026 | P13: À collecter | Q13: Gratuit à collecter : même fichier.
B14: rice_thai | C14: mensuelle | D14: Monde | E14: Monde | F14: Banque mondiale, Pink Sheet | G14: USD par tonne | H14: P1 | I14: Monde | J14: À coller | K14: Même fichier que oil_usd, « Rice, Thai 5% » | L14: https://thedocs.worldbank.org/en/doc/18675f1d1639c7a34d463f59263ba0a2-0050012025/related/CMO-Historical-Data-Monthly.xlsx | M14: FMI, PCPS | N14: Choc riz ; composante de import_food_idx | O14: Lien relevé ; contenu de mémoire | P14: À collecter | Q14: Le riz pèse 30,5 % des importations alimentaires de l'UEMOA (BCEAO 2023).
B15: wheat_hrw | C15: mensuelle | D15: Monde | E15: Monde | F15: Banque mondiale, Pink Sheet | G15: USD par tonne | H15: P1 | I15: Monde | J15: À coller | K15: Même fichier, « Wheat, US HRW » | L15: https://thedocs.worldbank.org/en/doc/18675f1d1639c7a34d463f59263ba0a2-0050012025/related/CMO-Historical-Data-Monthly.xlsx | M15: FMI, PCPS | N15: Choc blé ; composante de import_food_idx | O15: Lien relevé ; contenu de mémoire | P15: À collecter
B16: palm_oil | C16: mensuelle | D16: Monde | E16: Monde | F16: Banque mondiale, Pink Sheet | G16: USD par tonne | H16: P2 | I16: Monde | J16: À coller | K16: Même fichier, « Palm oil » | L16: https://thedocs.worldbank.org/en/doc/18675f1d1639c7a34d463f59263ba0a2-0050012025/related/CMO-Historical-Data-Monthly.xlsx | M16: FMI, PCPS | N16: Variante pour les huiles | O16: Lien relevé ; contenu de mémoire | P16: À collecter
B17: sugar_world | C17: mensuelle | D17: Monde | E17: Monde | F17: Banque mondiale, Pink Sheet | G17: USD par kg | H17: P1 | I17: Monde | J17: À coller | K17: Même fichier, « Sugar, world » | L17: https://thedocs.worldbank.org/en/doc/18675f1d1639c7a34d463f59263ba0a2-0050012025/related/CMO-Historical-Data-Monthly.xlsx | M17: FMI, PCPS | N17: Choc sucre ; composante de import_food_idx | O17: Lien relevé ; contenu de mémoire | P17: À collecter
B18: maize | C18: mensuelle | D18: Monde | E18: Monde | F18: Banque mondiale, Pink Sheet | G18: USD par tonne | H18: P2 | I18: Monde | J18: À coller | K18: Même fichier, « Maize » | L18: https://thedocs.worldbank.org/en/doc/18675f1d1639c7a34d463f59263ba0a2-0050012025/related/CMO-Historical-Data-Monthly.xlsx | M18: FMI, PCPS | N18: Complément (substituts locaux mil et sorgho) | O18: Lien relevé ; contenu de mémoire | P18: À collecter
B19: gscpi | C19: mensuelle | D19: Monde | E19: Monde | F19: Federal Reserve Bank of New York | G19: Écarts-types par rapport à la moyenne | H19: P1 | I19: Monde | J19: À coller | K19: Fichier de données de la page GSCPI | L19: https://www.newyorkfed.org/research/policy/gscpi | M19: Aucune | N19: Contrôle (fret et chaînes d'approvisionnement) | O19: Page ouverte le 02/10/2026 | P19: À collecter | Q19: Début de série (1998) cité de mémoire.
B20: bceao_import_food | C20: mensuelle | D20: Zone | E20: Zone UMOA | F20: BCEAO, Bulletin mensuel des statistiques, tableau 1.1.3.1 | G20: Indice, 100 = 01/01/2017 | H20: P1 | I20: Monde | J20: À coller | K20: « Cours mondiaux des principaux produits alimentaires » ; sources Bloomberg et FAO, calcul BCEAO | L20: https://www.bceao.int/fr/publications/bulletins | M20: import_food_idx (reconstruction) | N20: Choc alternatif propre à l'UEMOA (robustesse) | O20: Bulletin de janvier 2026 lu le 02/10/2026 | P20: À collecter | Q20: Chaque bulletin ne montre qu'une fenêtre de mois : l'historique se reconstitue bulletin par bulletin, ou via la base EDEN. Coûteux : après la baseline.
B21: import_food_idx | C21: mensuelle | D21: Zone | E21: Zone UMOA | F21: Calcul à partir des parts d'importation de BCEAO (2023), p. 11 | G21: Indice, 100 au premier mois complet | H21: P1 | I21: Monde | J21: Formule | K21: Aucun téléchargement : rice_thai, wheat_hrw, fao_oils, sugar_world, fao_dairy | L21: https://www.bceao.int/fr/publications/degre-de-transmission-des-prix-internationaux-dans-luemoa | M21: bceao_import_food | N21: Choc alternatif propre à l'UEMOA (robustesse) | O21: Calcul | P21: Sans objet | Q21: Reconstruction : les cinq produits couvrent 57,2 % des importations alimentaires ; poids dans Parametres.
B22: cpi_all_alt | C22: mensuelle | D22: Pays | E22: Pays zone UMOA | F22: Banque mondiale, Global Database of Inflation | G22: Indice | H22: P1 | I22: Onglets pays | J22: À coller | K22: Fichier Excel « Inflation data », feuille mensuelle de l'IPC total | L22: https://www.worldbank.org/en/research/brief/inflation-database | M22: FMI, CPI | N22: Recoupement de cpi_all | O22: Page ouverte le 02/10/2026 | P22: À collecter | Q22: Sert à repérer les mois estimés par FAOSTAT et les ruptures de base.
B23: cpi_food_alt | C23: mensuelle | D23: Pays | E23: Pays zone UMOA | F23: Banque mondiale, Global Database of Inflation | G23: Indice | H23: P1 | I23: Onglets pays | J23: À coller | K23: Même fichier, feuille mensuelle de l'IPC alimentaire | L23: https://www.worldbank.org/en/research/brief/inflation-database | M23: FMI, CPI détaillé | N23: Recoupement de cpi_food | O23: Page ouverte le 02/10/2026 | P23: À collecter
B24: quality_flag | C24: mensuelle | D24: Pays | E24: Pays zone UMOA | F24: FAOSTAT (flags) ou annotation manuelle | G24: Texte | H24: P1 | I24: Onglets pays | J24: À coller | K24: Flag FAOSTAT du mois (valeur officielle, estimée, etc.) | L24: https://data.apps.fao.org/catalog/dataset/941c71b7-137c-49a1-a128-3d71fb24a1de | M24: Aucune | N24: Filtre de robustesse (exclure les mois estimés) | O24: Page ouverte le 02/10/2026 | P24: À collecter
B25: rain_anom | C25: mensuelle | D25: Pays | E25: Pays zone UMOA | F25: PAM via HDX, Rainfall Indicators at Subnational Level (CHIRPS) | G25: % de la normale | H25: P2 | I25: Onglets pays | J25: À coller | K25: Un CSV par pays, agrégé au niveau national et au mois | L25: https://data.humdata.org/dataset/sen-rainfall-subnational | M25: Aucune | N25: Contrôle de l'offre agricole locale | O25: Trouvée par recherche | P25: À collecter | Q25: Seul substitut mensuel à la production céréalière. Identifiants des jeux dans l'onglet Pays.
B26: local_agri_supply | C26: annuelle | D26: Pays | E26: Pays zone UMOA | F26: FAOSTAT, Crops and livestock products (QCL) | G26: Tonnes | H26: P1 | I26: Annuel | J26: À coller | K26: « Cereals, primary », élément Production, 8 pays | L26: https://www.fao.org/faostat/en/#data/QCL | M26: Rapports BCEAO | N26: Contrôle de l'offre locale ; hétérogénéité | O26: De mémoire, à vérifier | P26: À collecter | Q26: Production annuelle par campagne : il n'existe pas de série mensuelle.
B27: import_dependency | C27: annuelle | D27: Pays | E27: Pays zone UMOA | F27: FAOSTAT, Suite of Food Security Indicators (FS) | G27: %, moyenne sur 3 ans | H27: P1 | I27: Annuel | J27: À coller | K27: « Cereal import dependency ratio (percent) (3-year average) » | L27: https://www.fao.org/faostat/en/#data/FS | M27: import_share_cpi (onglet Pays) | N27: Hétérogénéité (interaction avec le choc) | O27: Trouvée par recherche | P27: À collecter | Q27: Affecter la moyenne triennale à son année centrale.
B28: food_imports_share | C28: annuelle | D28: Pays | E28: Pays zone UMOA | F28: Banque mondiale, WDI | G28: % des importations de marchandises | H28: P2 | I28: Annuel | J28: À coller | K28: Indicateur TM.VAL.FOOD.ZS.UN | L28: https://data.worldbank.org/indicator/TM.VAL.FOOD.ZS.UN | M28: UN Comtrade | N28: Hétérogénéité (variante) | O28: De mémoire, à vérifier | P28: À collecter
B29: gdp_real | C29: annuelle | D29: Pays | E29: Pays zone UMOA | F29: FMI, World Economic Outlook | G29: Monnaie nationale constante | H29: P2 | I29: Annuel | J29: À coller | K29: Série NGDP_R | L29: https://www.imf.org/en/Publications/WEO/weo-database | M29: Banque mondiale, WDI | N29: Écart de production (robustesse annuelle) | O29: De mémoire, à vérifier | P29: À collecter
B30: coastal | C30: fixe | D30: Pays | E30: Pays zone UMOA | F30: Géographie | G30: 1 = côtier, 0 = enclavé | H30: P1 | I30: Pays | J30: Pré-rempli | K30: Aucun téléchargement | M30: Aucune | N30: Hétérogénéité | O30: Connaissance générale | P30: Sans objet
B31: food_weight | C31: fixe | D31: Pays | E31: Pays zone UMOA | F31: BCEAO (2023), tableau a2-1 | G31: % du panier | H31: P1 | I31: Pays | J31: Pré-rempli | K31: Aucun téléchargement | L31: https://www.bceao.int/fr/publications/degre-de-transmission-des-prix-internationaux-dans-luemoa | M31: FMI, CPI weights ; notes IHPC des instituts | N31: Hétérogénéité ; mise à l'échelle du choc | O31: Document lu le 02/10/2026 | P31: Sans objet | Q31: Pour l'inflation totale, un effet plus fort là où le poids est élevé est en partie mécanique.
B32: import_share_cpi | C32: fixe | D32: Pays | E32: Pays zone UMOA | F32: BCEAO (2023), graphique a2-4 | G32: % du panier | H32: P1 | I32: Pays | J32: Pré-rempli | K32: Aucun téléchargement | L32: https://www.bceao.int/fr/publications/degre-de-transmission-des-prix-internationaux-dans-luemoa | M32: import_dependency | N32: Hétérogénéité (interaction avec le choc) | O32: Document lu le 02/10/2026 | P32: Sans objet | Q32: Porte sur tout le panier, pas sur la seule alimentation.
B33: admin_prices, subsidies | C33: événementielle | D33: Pays | E33: Pays zone UMOA | F33: Sources nationales, rapports du FMI, BCEAO | G33: Qualitatif | H33: P2 | I33: Non collecté | J33: Non collecté | K33: Pas de base à construire | N33: Interprétation des réponses par pays | O33: Sans objet | P33: Non retenu | Q33: Trop coûteux à coder pour 8 pays ; fuel_adj_freq (onglet Pays) sert d'indice indirect.
B34: conflict_crisis | C34: mensuelle | D34: Pays | E34: Pays zone UMOA | F34: ACLED | G34: Nombre d'événements | H34: P2 | I34: Non collecté | J34: Non collecté | K34: Seulement si un épisode extrême doit être expliqué | L34: https://acleddata.com/ | M34: Aucune | N34: Robustesse | O34: De mémoire, à vérifier | P34: Non retenu | Q34: Inscription requise.

Sheet Monde
A2: Date | B2: fao_food | C2: fao_cereals | D2: fao_oils | E2: fao_sugar | F2: fao_dairy | G2: fao_meat | H2: oil_usd | I2: rice_thai | J2: wheat_hrw | K2: palm_oil | L2: sugar_world | M2: maize | N2: eur_usd | O2: usd_xof | P2: gscpi | Q2: bceao_import_food | R2: import_food_idx
A3: 2000-01 | O3: =IF(N3="","",Parametres!$C$3/N3) | R3: =IF(OR(I3="",J3="",D3="",L3="",F3=""),"",100)
A4: 2000-02 | O4: =IF(N4="","",Parametres!$C$3/N4) | R4: =IF(OR(I4="",J4="",D4="",L4="",F4=""),"",IF(R3="",100,R3*EXP(Parametres!$D$11*LN(I4/I3)+Parametres!$D$12*LN(J4/J3)+Parametres!$D$13*LN(D4/D3)+Parametres!$D$14*LN(L4/L3)+Parametres!$D$15*LN(F4/F3))))
A5: 2000-03 | O5: =IF(N5="","",Parametres!$C$3/N5) | R5: =IF(OR(I5="",J5="",D5="",L5="",F5=""),"",IF(R4="",100,R4*EXP(Parametres!$D$11*LN(I5/I4)+Parametres!$D$12*LN(J5/J4)+Parametres!$D$13*LN(D5/D4)+Parametres!$D$14*LN(L5/L4)+Parametres!$D$15*LN(F5/F4))))
A6: 2000-04 | O6: =IF(N6="","",Parametres!$C$3/N6) | R6: =IF(OR(I6="",J6="",D6="",L6="",F6=""),"",IF(R5="",100,R5*EXP(Parametres!$D$11*LN(I6/I5)+Parametres!$D$12*LN(J6/J5)+Parametres!$D$13*LN(D6/D5)+Parametres!$D$14*LN(L6/L5)+Parametres!$D$15*LN(F6/F5))))
A7: 2000-05 | O7: =IF(N7="","",Parametres!$C$3/N7) | R7: =IF(OR(I7="",J7="",D7="",L7="",F7=""),"",IF(R6="",100,R6*EXP(Parametres!$D$11*LN(I7/I6)+Parametres!$D$12*LN(J7/J6)+Parametres!$D$13*LN(D7/D6)+Parametres!$D$14*LN(L7/L6)+Parametres!$D$15*LN(F7/F6))))
A8: 2000-06 | O8: =IF(N8="","",Parametres!$C$3/N8) | R8: =IF(OR(I8="",J8="",D8="",L8="",F8=""),"",IF(R7="",100,R7*EXP(Parametres!$D$11*LN(I8/I7)+Parametres!$D$12*LN(J8/J7)+Parametres!$D$13*LN(D8/D7)+Parametres!$D$14*LN(L8/L7)+Parametres!$D$15*LN(F8/F7))))
A9: 2000-07 | O9: =IF(N9="","",Parametres!$C$3/N9) | R9: =IF(OR(I9="",J9="",D9="",L9="",F9=""),"",IF(R8="",100,R8*EXP(Parametres!$D$11*LN(I9/I8)+Parametres!$D$12*LN(J9/J8)+Parametres!$D$13*LN(D9/D8)+Parametres!$D$14*LN(L9/L8)+Parametres!$D$15*LN(F9/F8))))
A10: 2000-08 | O10: =IF(N10="","",Parametres!$C$3/N10) | R10: =IF(OR(I10="",J10="",D10="",L10="",F10=""),"",IF(R9="",100,R9*EXP(Parametres!$D$11*LN(I10/I9)+Parametres!$D$12*LN(J10/J9)+Parametres!$D$13*LN(D10/D9)+Parametres!$D$14*LN(L10/L9)+Parametres!$D$15*LN(F10/F9))))
A11: 2000-09 | O11: =IF(N11="","",Parametres!$C$3/N11) | R11: =IF(OR(I11="",J11="",D11="",L11="",F11=""),"",IF(R10="",100,R10*EXP(Parametres!$D$11*LN(I11/I10)+Parametres!$D$12*LN(J11/J10)+Parametres!$D$13*LN(D11/D10)+Parametres!$D$14*LN(L11/L10)+Parametres!$D$15*LN(F11/F10))))
A12: 2000-10 | O12: =IF(N12="","",Parametres!$C$3/N12) | R12: =IF(OR(I12="",J12="",D12="",L12="",F12=""),"",IF(R11="",100,R11*EXP(Parametres!$D$11*LN(I12/I11)+Parametres!$D$12*LN(J12/J11)+Parametres!$D$13*LN(D12/D11)+Parametres!$D$14*LN(L12/L11)+Parametres!$D$15*LN(F12/F11))))
A13: 2000-11 | O13: =IF(N13="","",Parametres!$C$3/N13) | R13: =IF(OR(I13="",J13="",D13="",L13="",F13=""),"",IF(R12="",100,R12*EXP(Parametres!$D$11*LN(I13/I12)+Parametres!$D$12*LN(J13/J12)+Parametres!$D$13*LN(D13/D12)+Parametres!$D$14*LN(L13/L12)+Parametres!$D$15*LN(F13/F12))))
A14: 2000-12 | O14: =IF(N14="","",Parametres!$C$3/N14) | R14: =IF(OR(I14="",J14="",D14="",L14="",F14=""),"",IF(R13="",100,R13*EXP(Parametres!$D$11*LN(I14/I13)+Parametres!$D$12*LN(J14/J13)+Parametres!$D$13*LN(D14/D13)+Parametres!$D$14*LN(L14/L13)+Parametres!$D$15*LN(F14/F13))))
A15: 2001-01 | O15: =IF(N15="","",Parametres!$C$3/N15) | R15: =IF(OR(I15="",J15="",D15="",L15="",F15=""),"",IF(R14="",100,R14*EXP(Parametres!$D$11*LN(I15/I14)+Parametres!$D$12*LN(J15/J14)+Parametres!$D$13*LN(D15/D14)+Parametres!$D$14*LN(L15/L14)+Parametres!$D$15*LN(F15/F14))))
... A323: 2026-09 | O323: =IF(N323="","",Parametres!$C$3/N323) | R323: =IF(OR(I323="",J323="",D323="",L323="",F323=""),"",IF(R322="",100,R322*EXP(Parametres!$D$11*LN(I323/I322)+Parametres!$D$12*LN(J323/J322)+Parametres!$D$13*LN(D323/D322)+Parametres!$D$14*LN(L323/L322)+Parametres!$D$15*LN(F323/F322))))

Sheet BEN
A2: Date | B2: cpi_all | C2: cpi_food | D2: fao_food | E2: oil_usd | F2: usd_xof | G2: fao_cereals | H2: fao_oils | I2: fao_sugar | J2: fao_dairy | K2: fao_meat | L2: rice_thai | M2: wheat_hrw | N2: palm_oil | O2: sugar_world | P2: maize | Q2: eur_usd | R2: gscpi | S2: bceao_import_food | T2: import_food_idx | U2: cpi_all_alt | V2: cpi_food_alt | W2: rain_anom | X2: quality_flag | Y2: note
A3: 2000-01 | D3: =IF(Monde!B3="","",Monde!B3) | E3: =IF(Monde!H3="","",Monde!H3) | F3: =IF(Monde!O3="","",Monde!O3) | G3: =IF(Monde!C3="","",Monde!C3) | H3: =IF(Monde!D3="","",Monde!D3) | I3: =IF(Monde!E3="","",Monde!E3) | J3: =IF(Monde!F3="","",Monde!F3) | K3: =IF(Monde!G3="","",Monde!G3) | L3: =IF(Monde!I3="","",Monde!I3) | M3: =IF(Monde!J3="","",Monde!J3) | N3: =IF(Monde!K3="","",Monde!K3) | O3: =IF(Monde!L3="","",Monde!L3) | P3: =IF(Monde!M3="","",Monde!M3) | Q3: =IF(Monde!N3="","",Monde!N3) | R3: =IF(Monde!P3="","",Monde!P3) | S3: =IF(Monde!Q3="","",Monde!Q3) | T3: =IF(Monde!R3="","",Monde!R3)
A4: 2000-02 | D4: =IF(Monde!B4="","",Monde!B4) | E4: =IF(Monde!H4="","",Monde!H4) | F4: =IF(Monde!O4="","",Monde!O4) | G4: =IF(Monde!C4="","",Monde!C4) | H4: =IF(Monde!D4="","",Monde!D4) | I4: =IF(Monde!E4="","",Monde!E4) | J4: =IF(Monde!F4="","",Monde!F4) | K4: =IF(Monde!G4="","",Monde!G4) | L4: =IF(Monde!I4="","",Monde!I4) | M4: =IF(Monde!J4="","",Monde!J4) | N4: =IF(Monde!K4="","",Monde!K4) | O4: =IF(Monde!L4="","",Monde!L4) | P4: =IF(Monde!M4="","",Monde!M4) | Q4: =IF(Monde!N4="","",Monde!N4) | R4: =IF(Monde!P4="","",Monde!P4) | S4: =IF(Monde!Q4="","",Monde!Q4) | T4: =IF(Monde!R4="","",Monde!R4)
A5: 2000-03 | D5: =IF(Monde!B5="","",Monde!B5) | E5: =IF(Monde!H5="","",Monde!H5) | F5: =IF(Monde!O5="","",Monde!O5) | G5: =IF(Monde!C5="","",Monde!C5) | H5: =IF(Monde!D5="","",Monde!D5) | I5: =IF(Monde!E5="","",Monde!E5) | J5: =IF(Monde!F5="","",Monde!F5) | K5: =IF(Monde!G5="","",Monde!G5) | L5: =IF(Monde!I5="","",Monde!I5) | M5: =IF(Monde!J5="","",Monde!J5) | N5: =IF(Monde!K5="","",Monde!K5) | O5: =IF(Monde!L5="","",Monde!L5) | P5: =IF(Monde!M5="","",Monde!M5) | Q5: =IF(Monde!N5="","",Monde!N5) | R5: =IF(Monde!P5="","",Monde!P5) | S5: =IF(Monde!Q5="","",Monde!Q5) | T5: =IF(Monde!R5="","",Monde!R5)
A6: 2000-04 | D6: =IF(Monde!B6="","",Monde!B6) | E6: =IF(Monde!H6="","",Monde!H6) | F6: =IF(Monde!O6="","",Monde!O6) | G6: =IF(Monde!C6="","",Monde!C6) | H6: =IF(Monde!D6="","",Monde!D6) | I6: =IF(Monde!E6="","",Monde!E6) | J6: =IF(Monde!F6="","",Monde!F6) | K6: =IF(Monde!G6="","",Monde!G6) | L6: =IF(Monde!I6="","",Monde!I6) | M6: =IF(Monde!J6="","",Monde!J6) | N6: =IF(Monde!K6="","",Monde!K6) | O6: =IF(Monde!L6="","",Monde!L6) | P6: =IF(Monde!M6="","",Monde!M6) | Q6: =IF(Monde!N6="","",Monde!N6) | R6: =IF(Monde!P6="","",Monde!P6) | S6: =IF(Monde!Q6="","",Monde!Q6) | T6: =IF(Monde!R6="","",Monde!R6)
A7: 2000-05 | D7: =IF(Monde!B7="","",Monde!B7) | E7: =IF(Monde!H7="","",Monde!H7) | F7: =IF(Monde!O7="","",Monde!O7) | G7: =IF(Monde!C7="","",Monde!C7) | H7: =IF(Monde!D7="","",Monde!D7) | I7: =IF(Monde!E7="","",Monde!E7) | J7: =IF(Monde!F7="","",Monde!F7) | K7: =IF(Monde!G7="","",Monde!G7) | L7: =IF(Monde!I7="","",Monde!I7) | M7: =IF(Monde!J7="","",Monde!J7) | N7: =IF(Monde!K7="","",Monde!K7) | O7: =IF(Monde!L7="","",Monde!L7) | P7: =IF(Monde!M7="","",Monde!M7) | Q7: =IF(Monde!N7="","",Monde!N7) | R7: =IF(Monde!P7="","",Monde!P7) | S7: =IF(Monde!Q7="","",Monde!Q7) | T7: =IF(Monde!R7="","",Monde!R7)
A8: 2000-06 | D8: =IF(Monde!B8="","",Monde!B8) | E8: =IF(Monde!H8="","",Monde!H8) | F8: =IF(Monde!O8="","",Monde!O8) | G8: =IF(Monde!C8="","",Monde!C8) | H8: =IF(Monde!D8="","",Monde!D8) | I8: =IF(Monde!E8="","",Monde!E8) | J8: =IF(Monde!F8="","",Monde!F8) | K8: =IF(Monde!G8="","",Monde!G8) | L8: =IF(Monde!I8="","",Monde!I8) | M8: =IF(Monde!J8="","",Monde!J8) | N8: =IF(Monde!K8="","",Monde!K8) | O8: =IF(Monde!L8="","",Monde!L8) | P8: =IF(Monde!M8="","",Monde!M8) | Q8: =IF(Monde!N8="","",Monde!N8) | R8: =IF(Monde!P8="","",Monde!P8) | S8: =IF(Monde!Q8="","",Monde!Q8) | T8: =IF(Monde!R8="","",Monde!R8)
A9: 2000-07 | D9: =IF(Monde!B9="","",Monde!B9) | E9: =IF(Monde!H9="","",Monde!H9) | F9: =IF(Monde!O9="","",Monde!O9) | G9: =IF(Monde!C9="","",Monde!C9) | H9: =IF(Monde!D9="","",Monde!D9) | I9: =IF(Monde!E9="","",Monde!E9) | J9: =IF(Monde!F9="","",Monde!F9) | K9: =IF(Monde!G9="","",Monde!G9) | L9: =IF(Monde!I9="","",Monde!I9) | M9: =IF(Monde!J9="","",Monde!J9) | N9: =IF(Monde!K9="","",Monde!K9) | O9: =IF(Monde!L9="","",Monde!L9) | P9: =IF(Monde!M9="","",Monde!M9) | Q9: =IF(Monde!N9="","",Monde!N9) | R9: =IF(Monde!P9="","",Monde!P9) | S9: =IF(Monde!Q9="","",Monde!Q9) | T9: =IF(Monde!R9="","",Monde!R9)
A10: 2000-08 | D10: =IF(Monde!B10="","",Monde!B10) | E10: =IF(Monde!H10="","",Monde!H10) | F10: =IF(Monde!O10="","",Monde!O10) | G10: =IF(Monde!C10="","",Monde!C10) | H10: =IF(Monde!D10="","",Monde!D10) | I10: =IF(Monde!E10="","",Monde!E10) | J10: =IF(Monde!F10="","",Monde!F10) | K10: =IF(Monde!G10="","",Monde!G10) | L10: =IF(Monde!I10="","",Monde!I10) | M10: =IF(Monde!J10="","",Monde!J10) | N10: =IF(Monde!K10="","",Monde!K10) | O10: =IF(Monde!L10="","",Monde!L10) | P10: =IF(Monde!M10="","",Monde!M10) | Q10: =IF(Monde!N10="","",Monde!N10) | R10: =IF(Monde!P10="","",Monde!P10) | S10: =IF(Monde!Q10="","",Monde!Q10) | T10: =IF(Monde!R10="","",Monde!R10)
A11: 2000-09 | D11: =IF(Monde!B11="","",Monde!B11) | E11: =IF(Monde!H11="","",Monde!H11) | F11: =IF(Monde!O11="","",Monde!O11) | G11: =IF(Monde!C11="","",Monde!C11) | H11: =IF(Monde!D11="","",Monde!D11) | I11: =IF(Monde!E11="","",Monde!E11) | J11: =IF(Monde!F11="","",Monde!F11) | K11: =IF(Monde!G11="","",Monde!G11) | L11: =IF(Monde!I11="","",Monde!I11) | M11: =IF(Monde!J11="","",Monde!J11) | N11: =IF(Monde!K11="","",Monde!K11) | O11: =IF(Monde!L11="","",Monde!L11) | P11: =IF(Monde!M11="","",Monde!M11) | Q11: =IF(Monde!N11="","",Monde!N11) | R11: =IF(Monde!P11="","",Monde!P11) | S11: =IF(Monde!Q11="","",Monde!Q11) | T11: =IF(Monde!R11="","",Monde!R11)
A12: 2000-10 | D12: =IF(Monde!B12="","",Monde!B12) | E12: =IF(Monde!H12="","",Monde!H12) | F12: =IF(Monde!O12="","",Monde!O12) | G12: =IF(Monde!C12="","",Monde!C12) | H12: =IF(Monde!D12="","",Monde!D12) | I12: =IF(Monde!E12="","",Monde!E12) | J12: =IF(Monde!F12="","",Monde!F12) | K12: =IF(Monde!G12="","",Monde!G12) | L12: =IF(Monde!I12="","",Monde!I12) | M12: =IF(Monde!J12="","",Monde!J12) | N12: =IF(Monde!K12="","",Monde!K12) | O12: =IF(Monde!L12="","",Monde!L12) | P12: =IF(Monde!M12="","",Monde!M12) | Q12: =IF(Monde!N12="","",Monde!N12) | R12: =IF(Monde!P12="","",Monde!P12) | S12: =IF(Monde!Q12="","",Monde!Q12) | T12: =IF(Monde!R12="","",Monde!R12)
A13: 2000-11 | D13: =IF(Monde!B13="","",Monde!B13) | E13: =IF(Monde!H13="","",Monde!H13) | F13: =IF(Monde!O13="","",Monde!O13) | G13: =IF(Monde!C13="","",Monde!C13) | H13: =IF(Monde!D13="","",Monde!D13) | I13: =IF(Monde!E13="","",Monde!E13) | J13: =IF(Monde!F13="","",Monde!F13) | K13: =IF(Monde!G13="","",Monde!G13) | L13: =IF(Monde!I13="","",Monde!I13) | M13: =IF(Monde!J13="","",Monde!J13) | N13: =IF(Monde!K13="","",Monde!K13) | O13: =IF(Monde!L13="","",Monde!L13) | P13: =IF(Monde!M13="","",Monde!M13) | Q13: =IF(Monde!N13="","",Monde!N13) | R13: =IF(Monde!P13="","",Monde!P13) | S13: =IF(Monde!Q13="","",Monde!Q13) | T13: =IF(Monde!R13="","",Monde!R13)
A14: 2000-12 | D14: =IF(Monde!B14="","",Monde!B14) | E14: =IF(Monde!H14="","",Monde!H14) | F14: =IF(Monde!O14="","",Monde!O14) | G14: =IF(Monde!C14="","",Monde!C14) | H14: =IF(Monde!D14="","",Monde!D14) | I14: =IF(Monde!E14="","",Monde!E14) | J14: =IF(Monde!F14="","",Monde!F14) | K14: =IF(Monde!G14="","",Monde!G14) | L14: =IF(Monde!I14="","",Monde!I14) | M14: =IF(Monde!J14="","",Monde!J14) | N14: =IF(Monde!K14="","",Monde!K14) | O14: =IF(Monde!L14="","",Monde!L14) | P14: =IF(Monde!M14="","",Monde!M14) | Q14: =IF(Monde!N14="","",Monde!N14) | R14: =IF(Monde!P14="","",Monde!P14) | S14: =IF(Monde!Q14="","",Monde!Q14) | T14: =IF(Monde!R14="","",Monde!R14)
... A323: 2026-09 | D323: =IF(Monde!B323="","",Monde!B323) | E323: =IF(Monde!H323="","",Monde!H323) | F323: =IF(Monde!O323="","",Monde!O323) | G323: =IF(Monde!C323="","",Monde!C323) | H323: =IF(Monde!D323="","",Monde!D323) | I323: =IF(Monde!E323="","",Monde!E323) | J323: =IF(Monde!F323="","",Monde!F323) | K323: =IF(Monde!G323="","",Monde!G323) | L323: =IF(Monde!I323="","",Monde!I323) | M323: =IF(Monde!J323="","",Monde!J323) | N323: =IF(Monde!K323="","",Monde!K323) | O323: =IF(Monde!L323="","",Monde!L323) | P323: =IF(Monde!M323="","",Monde!M323) | Q323: =IF(Monde!N323="","",Monde!N323) | R323: =IF(Monde!P323="","",Monde!P323) | S323: =IF(Monde!Q323="","",Monde!Q323) | T323: =IF(Monde!R323="","",Monde!R323)

Sheet BFA
A2: Date | B2: cpi_all | C2: cpi_food | D2: fao_food | E2: oil_usd | F2: usd_xof | G2: fao_cereals | H2: fao_oils | I2: fao_sugar | J2: fao_dairy | K2: fao_meat | L2: rice_thai | M2: wheat_hrw | N2: palm_oil | O2: sugar_world | P2: maize | Q2: eur_usd | R2: gscpi | S2: bceao_import_food | T2: import_food_idx | U2: cpi_all_alt | V2: cpi_food_alt | W2: rain_anom | X2: quality_flag | Y2: note
A3: 2000-01 | D3: =IF(Monde!B3="","",Monde!B3) | E3: =IF(Monde!H3="","",Monde!H3) | F3: =IF(Monde!O3="","",Monde!O3) | G3: =IF(Monde!C3="","",Monde!C3) | H3: =IF(Monde!D3="","",Monde!D3) | I3: =IF(Monde!E3="","",Monde!E3) | J3: =IF(Monde!F3="","",Monde!F3) | K3: =IF(Monde!G3="","",Monde!G3) | L3: =IF(Monde!I3="","",Monde!I3) | M3: =IF(Monde!J3="","",Monde!J3) | N3: =IF(Monde!K3="","",Monde!K3) | O3: =IF(Monde!L3="","",Monde!L3) | P3: =IF(Monde!M3="","",Monde!M3) | Q3: =IF(Monde!N3="","",Monde!N3) | R3: =IF(Monde!P3="","",Monde!P3) | S3: =IF(Monde!Q3="","",Monde!Q3) | T3: =IF(Monde!R3="","",Monde!R3)
A4: 2000-02 | D4: =IF(Monde!B4="","",Monde!B4) | E4: =IF(Monde!H4="","",Monde!H4) | F4: =IF(Monde!O4="","",Monde!O4) | G4: =IF(Monde!C4="","",Monde!C4) | H4: =IF(Monde!D4="","",Monde!D4) | I4: =IF(Monde!E4="","",Monde!E4) | J4: =IF(Monde!F4="","",Monde!F4) | K4: =IF(Monde!G4="","",Monde!G4) | L4: =IF(Monde!I4="","",Monde!I4) | M4: =IF(Monde!J4="","",Monde!J4) | N4: =IF(Monde!K4="","",Monde!K4) | O4: =IF(Monde!L4="","",Monde!L4) | P4: =IF(Monde!M4="","",Monde!M4) | Q4: =IF(Monde!N4="","",Monde!N4) | R4: =IF(Monde!P4="","",Monde!P4) | S4: =IF(Monde!Q4="","",Monde!Q4) | T4: =IF(Monde!R4="","",Monde!R4)
A5: 2000-03 | D5: =IF(Monde!B5="","",Monde!B5) | E5: =IF(Monde!H5="","",Monde!H5) | F5: =IF(Monde!O5="","",Monde!O5) | G5: =IF(Monde!C5="","",Monde!C5) | H5: =IF(Monde!D5="","",Monde!D5) | I5: =IF(Monde!E5="","",Monde!E5) | J5: =IF(Monde!F5="","",Monde!F5) | K5: =IF(Monde!G5="","",Monde!G5) | L5: =IF(Monde!I5="","",Monde!I5) | M5: =IF(Monde!J5="","",Monde!J5) | N5: =IF(Monde!K5="","",Monde!K5) | O5: =IF(Monde!L5="","",Monde!L5) | P5: =IF(Monde!M5="","",Monde!M5) | Q5: =IF(Monde!N5="","",Monde!N5) | R5: =IF(Monde!P5="","",Monde!P5) | S5: =IF(Monde!Q5="","",Monde!Q5) | T5: =IF(Monde!R5="","",Monde!R5)
A6: 2000-04 | D6: =IF(Monde!B6="","",Monde!B6) | E6: =IF(Monde!H6="","",Monde!H6) | F6: =IF(Monde!O6="","",Monde!O6) | G6: =IF(Monde!C6="","",Monde!C6) | H6: =IF(Monde!D6="","",Monde!D6) | I6: =IF(Monde!E6="","",Monde!E6) | J6: =IF(Monde!F6="","",Monde!F6) | K6: =IF(Monde!G6="","",Monde!G6) | L6: =IF(Monde!I6="","",Monde!I6) | M6: =IF(Monde!J6="","",Monde!J6) | N6: =IF(Monde!K6="","",Monde!K6) | O6: =IF(Monde!L6="","",Monde!L6) | P6: =IF(Monde!M6="","",Monde!M6) | Q6: =IF(Monde!N6="","",Monde!N6) | R6: =IF(Monde!P6="","",Monde!P6) | S6: =IF(Monde!Q6="","",Monde!Q6) | T6: =IF(Monde!R6="","",Monde!R6)
A7: 2000-05 | D7: =IF(Monde!B7="","",Monde!B7) | E7: =IF(Monde!H7="","",Monde!H7) | F7: =IF(Monde!O7="","",Monde!O7) | G7: =IF(Monde!C7="","",Monde!C7) | H7: =IF(Monde!D7="","",Monde!D7) | I7: =IF(Monde!E7="","",Monde!E7) | J7: =IF(Monde!F7="","",Monde!F7) | K7: =IF(Monde!G7="","",Monde!G7) | L7: =IF(Monde!I7="","",Monde!I7) | M7: =IF(Monde!J7="","",Monde!J7) | N7: =IF(Monde!K7="","",Monde!K7) | O7: =IF(Monde!L7="","",Monde!L7) | P7: =IF(Monde!M7="","",Monde!M7) | Q7: =IF(Monde!N7="","",Monde!N7) | R7: =IF(Monde!P7="","",Monde!P7) | S7: =IF(Monde!Q7="","",Monde!Q7) | T7: =IF(Monde!R7="","",Monde!R7)
A8: 2000-06 | D8: =IF(Monde!B8="","",Monde!B8) | E8: =IF(Monde!H8="","",Monde!H8) | F8: =IF(Monde!O8="","",Monde!O8) | G8: =IF(Monde!C8="","",Monde!C8) | H8: =IF(Monde!D8="","",Monde!D8) | I8: =IF(Monde!E8="","",Monde!E8) | J8: =IF(Monde!F8="","",Monde!F8) | K8: =IF(Monde!G8="","",Monde!G8) | L8: =IF(Monde!I8="","",Monde!I8) | M8: =IF(Monde!J8="","",Monde!J8) | N8: =IF(Monde!K8="","",Monde!K8) | O8: =IF(Monde!L8="","",Monde!L8) | P8: =IF(Monde!M8="","",Monde!M8) | Q8: =IF(Monde!N8="","",Monde!N8) | R8: =IF(Monde!P8="","",Monde!P8) | S8: =IF(Monde!Q8="","",Monde!Q8) | T8: =IF(Monde!R8="","",Monde!R8)
A9: 2000-07 | D9: =IF(Monde!B9="","",Monde!B9) | E9: =IF(Monde!H9="","",Monde!H9) | F9: =IF(Monde!O9="","",Monde!O9) | G9: =IF(Monde!C9="","",Monde!C9) | H9: =IF(Monde!D9="","",Monde!D9) | I9: =IF(Monde!E9="","",Monde!E9) | J9: =IF(Monde!F9="","",Monde!F9) | K9: =IF(Monde!G9="","",Monde!G9) | L9: =IF(Monde!I9="","",Monde!I9) | M9: =IF(Monde!J9="","",Monde!J9) | N9: =IF(Monde!K9="","",Monde!K9) | O9: =IF(Monde!L9="","",Monde!L9) | P9: =IF(Monde!M9="","",Monde!M9) | Q9: =IF(Monde!N9="","",Monde!N9) | R9: =IF(Monde!P9="","",Monde!P9) | S9: =IF(Monde!Q9="","",Monde!Q9) | T9: =IF(Monde!R9="","",Monde!R9)
A10: 2000-08 | D10: =IF(Monde!B10="","",Monde!B10) | E10: =IF(Monde!H10="","",Monde!H10) | F10: =IF(Monde!O10="","",Monde!O10) | G10: =IF(Monde!C10="","",Monde!C10) | H10: =IF(Monde!D10="","",Monde!D10) | I10: =IF(Monde!E10="","",Monde!E10) | J10: =IF(Monde!F10="","",Monde!F10) | K10: =IF(Monde!G10="","",Monde!G10) | L10: =IF(Monde!I10="","",Monde!I10) | M10: =IF(Monde!J10="","",Monde!J10) | N10: =IF(Monde!K10="","",Monde!K10) | O10: =IF(Monde!L10="","",Monde!L10) | P10: =IF(Monde!M10="","",Monde!M10) | Q10: =IF(Monde!N10="","",Monde!N10) | R10: =IF(Monde!P10="","",Monde!P10) | S10: =IF(Monde!Q10="","",Monde!Q10) | T10: =IF(Monde!R10="","",Monde!R10)
A11: 2000-09 | D11: =IF(Monde!B11="","",Monde!B11) | E11: =IF(Monde!H11="","",Monde!H11) | F11: =IF(Monde!O11="","",Monde!O11) | G11: =IF(Monde!C11="","",Monde!C11) | H11: =IF(Monde!D11="","",Monde!D11) | I11: =IF(Monde!E11="","",Monde!E11) | J11: =IF(Monde!F11="","",Monde!F11) | K11: =IF(Monde!G11="","",Monde!G11) | L11: =IF(Monde!I11="","",Monde!I11) | M11: =IF(Monde!J11="","",Monde!J11) | N11: =IF(Monde!K11="","",Monde!K11) | O11: =IF(Monde!L11="","",Monde!L11) | P11: =IF(Monde!M11="","",Monde!M11) | Q11: =IF(Monde!N11="","",Monde!N11) | R11: =IF(Monde!P11="","",Monde!P11) | S11: =IF(Monde!Q11="","",Monde!Q11) | T11: =IF(Monde!R11="","",Monde!R11)
A12: 2000-10 | D12: =IF(Monde!B12="","",Monde!B12) | E12: =IF(Monde!H12="","",Monde!H12) | F12: =IF(Monde!O12="","",Monde!O12) | G12: =IF(Monde!C12="","",Monde!C12) | H12: =IF(Monde!D12="","",Monde!D12) | I12: =IF(Monde!E12="","",Monde!E12) | J12: =IF(Monde!F12="","",Monde!F12) | K12: =IF(Monde!G12="","",Monde!G12) | L12: =IF(Monde!I12="","",Monde!I12) | M12: =IF(Monde!J12="","",Monde!J12) | N12: =IF(Monde!K12="","",Monde!K12) | O12: =IF(Monde!L12="","",Monde!L12) | P12: =IF(Monde!M12="","",Monde!M12) | Q12: =IF(Monde!N12="","",Monde!N12) | R12: =IF(Monde!P12="","",Monde!P12) | S12: =IF(Monde!Q12="","",Monde!Q12) | T12: =IF(Monde!R12="","",Monde!R12)
A13: 2000-11 | D13: =IF(Monde!B13="","",Monde!B13) | E13: =IF(Monde!H13="","",Monde!H13) | F13: =IF(Monde!O13="","",Monde!O13) | G13: =IF(Monde!C13="","",Monde!C13) | H13: =IF(Monde!D13="","",Monde!D13) | I13: =IF(Monde!E13="","",Monde!E13) | J13: =IF(Monde!F13="","",Monde!F13) | K13: =IF(Monde!G13="","",Monde!G13) | L13: =IF(Monde!I13="","",Monde!I13) | M13: =IF(Monde!J13="","",Monde!J13) | N13: =IF(Monde!K13="","",Monde!K13) | O13: =IF(Monde!L13="","",Monde!L13) | P13: =IF(Monde!M13="","",Monde!M13) | Q13: =IF(Monde!N13="","",Monde!N13) | R13: =IF(Monde!P13="","",Monde!P13) | S13: =IF(Monde!Q13="","",Monde!Q13) | T13: =IF(Monde!R13="","",Monde!R13)
A14: 2000-12 | D14: =IF(Monde!B14="","",Monde!B14) | E14: =IF(Monde!H14="","",Monde!H14) | F14: =IF(Monde!O14="","",Monde!O14) | G14: =IF(Monde!C14="","",Monde!C14) | H14: =IF(Monde!D14="","",Monde!D14) | I14: =IF(Monde!E14="","",Monde!E14) | J14: =IF(Monde!F14="","",Monde!F14) | K14: =IF(Monde!G14="","",Monde!G14) | L14: =IF(Monde!I14="","",Monde!I14) | M14: =IF(Monde!J14="","",Monde!J14) | N14: =IF(Monde!K14="","",Monde!K14) | O14: =IF(Monde!L14="","",Monde!L14) | P14: =IF(Monde!M14="","",Monde!M14) | Q14: =IF(Monde!N14="","",Monde!N14) | R14: =IF(Monde!P14="","",Monde!P14) | S14: =IF(Monde!Q14="","",Monde!Q14) | T14: =IF(Monde!R14="","",Monde!R14)
... A323: 2026-09 | D323: =IF(Monde!B323="","",Monde!B323) | E323: =IF(Monde!H323="","",Monde!H323) | F323: =IF(Monde!O323="","",Monde!O323) | G323: =IF(Monde!C323="","",Monde!C323) | H323: =IF(Monde!D323="","",Monde!D323) | I323: =IF(Monde!E323="","",Monde!E323) | J323: =IF(Monde!F323="","",Monde!F323) | K323: =IF(Monde!G323="","",Monde!G323) | L323: =IF(Monde!I323="","",Monde!I323) | M323: =IF(Monde!J323="","",Monde!J323) | N323: =IF(Monde!K323="","",Monde!K323) | O323: =IF(Monde!L323="","",Monde!L323) | P323: =IF(Monde!M323="","",Monde!M323) | Q323: =IF(Monde!N323="","",Monde!N323) | R323: =IF(Monde!P323="","",Monde!P323) | S323: =IF(Monde!Q323="","",Monde!Q323) | T323: =IF(Monde!R323="","",Monde!R323)

Sheet CIV
A2: Date | B2: cpi_all | C2: cpi_food | D2: fao_food | E2: oil_usd | F2: usd_xof | G2: fao_cereals | H2: fao_oils | I2: fao_sugar | J2: fao_dairy | K2: fao_meat | L2: rice_thai | M2: wheat_hrw | N2: palm_oil | O2: sugar_world | P2: maize | Q2: eur_usd | R2: gscpi | S2: bceao_import_food | T2: import_food_idx | U2: cpi_all_alt | V2: cpi_food_alt | W2: rain_anom | X2: quality_flag | Y2: note
A3: 2000-01 | D3: =IF(Monde!B3="","",Monde!B3) | E3: =IF(Monde!H3="","",Monde!H3) | F3: =IF(Monde!O3="","",Monde!O3) | G3: =IF(Monde!C3="","",Monde!C3) | H3: =IF(Monde!D3="","",Monde!D3) | I3: =IF(Monde!E3="","",Monde!E3) | J3: =IF(Monde!F3="","",Monde!F3) | K3: =IF(Monde!G3="","",Monde!G3) | L3: =IF(Monde!I3="","",Monde!I3) | M3: =IF(Monde!J3="","",Monde!J3) | N3: =IF(Monde!K3="","",Monde!K3) | O3: =IF(Monde!L3="","",Monde!L3) | P3: =IF(Monde!M3="","",Monde!M3) | Q3: =IF(Monde!N3="","",Monde!N3) | R3: =IF(Monde!P3="","",Monde!P3) | S3: =IF(Monde!Q3="","",Monde!Q3) | T3: =IF(Monde!R3="","",Monde!R3)
A4: 2000-02 | D4: =IF(Monde!B4="","",Monde!B4) | E4: =IF(Monde!H4="","",Monde!H4) | F4: =IF(Monde!O4="","",Monde!O4) | G4: =IF(Monde!C4="","",Monde!C4) | H4: =IF(Monde!D4="","",Monde!D4) | I4: =IF(Monde!E4="","",Monde!E4) | J4: =IF(Monde!F4="","",Monde!F4) | K4: =IF(Monde!G4="","",Monde!G4) | L4: =IF(Monde!I4="","",Monde!I4) | M4: =IF(Monde!J4="","",Monde!J4) | N4: =IF(Monde!K4="","",Monde!K4) | O4: =IF(Monde!L4="","",Monde!L4) | P4: =IF(Monde!M4="","",Monde!M4) | Q4: =IF(Monde!N4="","",Monde!N4) | R4: =IF(Monde!P4="","",Monde!P4) | S4: =IF(Monde!Q4="","",Monde!Q4) | T4: =IF(Monde!R4="","",Monde!R4)
A5: 2000-03 | D5: =IF(Monde!B5="","",Monde!B5) | E5: =IF(Monde!H5="","",Monde!H5) | F5: =IF(Monde!O5="","",Monde!O5) | G5: =IF(Monde!C5="","",Monde!C5) | H5: =IF(Monde!D5="","",Monde!D5) | I5: =IF(Monde!E5="","",Monde!E5) | J5: =IF(Monde!F5="","",Monde!F5) | K5: =IF(Monde!G5="","",Monde!G5) | L5: =IF(Monde!I5="","",Monde!I5) | M5: =IF(Monde!J5="","",Monde!J5) | N5: =IF(Monde!K5="","",Monde!K5) | O5: =IF(Monde!L5="","",Monde!L5) | P5: =IF(Monde!M5="","",Monde!M5) | Q5: =IF(Monde!N5="","",Monde!N5) | R5: =IF(Monde!P5="","",Monde!P5) | S5: =IF(Monde!Q5="","",Monde!Q5) | T5: =IF(Monde!R5="","",Monde!R5)
A6: 2000-04 | D6: =IF(Monde!B6="","",Monde!B6) | E6: =IF(Monde!H6="","",Monde!H6) | F6: =IF(Monde!O6="","",Monde!O6) | G6: =IF(Monde!C6="","",Monde!C6) | H6: =IF(Monde!D6="","",Monde!D6) | I6: =IF(Monde!E6="","",Monde!E6) | J6: =IF(Monde!F6="","",Monde!F6) | K6: =IF(Monde!G6="","",Monde!G6) | L6: =IF(Monde!I6="","",Monde!I6) | M6: =IF(Monde!J6="","",Monde!J6) | N6: =IF(Monde!K6="","",Monde!K6) | O6: =IF(Monde!L6="","",Monde!L6) | P6: =IF(Monde!M6="","",Monde!M6) | Q6: =IF(Monde!N6="","",Monde!N6) | R6: =IF(Monde!P6="","",Monde!P6) | S6: =IF(Monde!Q6="","",Monde!Q6) | T6: =IF(Monde!R6="","",Monde!R6)
A7: 2000-05 | D7: =IF(Monde!B7="","",Monde!B7) | E7: =IF(Monde!H7="","",Monde!H7) | F7: =IF(Monde!O7="","",Monde!O7) | G7: =IF(Monde!C7="","",Monde!C7) | H7: =IF(Monde!D7="","",Monde!D7) | I7: =IF(Monde!E7="","",Monde!E7) | J7: =IF(Monde!F7="","",Monde!F7) | K7: =IF(Monde!G7="","",Monde!G7) | L7: =IF(Monde!I7="","",Monde!I7) | M7: =IF(Monde!J7="","",Monde!J7) | N7: =IF(Monde!K7="","",Monde!K7) | O7: =IF(Monde!L7="","",Monde!L7) | P7: =IF(Monde!M7="","",Monde!M7) | Q7: =IF(Monde!N7="","",Monde!N7) | R7: =IF(Monde!P7="","",Monde!P7) | S7: =IF(Monde!Q7="","",Monde!Q7) | T7: =IF(Monde!R7="","",Monde!R7)
A8: 2000-06 | D8: =IF(Monde!B8="","",Monde!B8) | E8: =IF(Monde!H8="","",Monde!H8) | F8: =IF(Monde!O8="","",Monde!O8) | G8: =IF(Monde!C8="","",Monde!C8) | H8: =IF(Monde!D8="","",Monde!D8) | I8: =IF(Monde!E8="","",Monde!E8) | J8: =IF(Monde!F8="","",Monde!F8) | K8: =IF(Monde!G8="","",Monde!G8) | L8: =IF(Monde!I8="","",Monde!I8) | M8: =IF(Monde!J8="","",Monde!J8) | N8: =IF(Monde!K8="","",Monde!K8) | O8: =IF(Monde!L8="","",Monde!L8) | P8: =IF(Monde!M8="","",Monde!M8) | Q8: =IF(Monde!N8="","",Monde!N8) | R8: =IF(Monde!P8="","",Monde!P8) | S8: =IF(Monde!Q8="","",Monde!Q8) | T8: =IF(Monde!R8="","",Monde!R8)
A9: 2000-07 | D9: =IF(Monde!B9="","",Monde!B9) | E9: =IF(Monde!H9="","",Monde!H9) | F9: =IF(Monde!O9="","",Monde!O9) | G9: =IF(Monde!C9="","",Monde!C9) | H9: =IF(Monde!D9="","",Monde!D9) | I9: =IF(Monde!E9="","",Monde!E9) | J9: =IF(Monde!F9="","",Monde!F9) | K9: =IF(Monde!G9="","",Monde!G9) | L9: =IF(Monde!I9="","",Monde!I9) | M9: =IF(Monde!J9="","",Monde!J9) | N9: =IF(Monde!K9="","",Monde!K9) | O9: =IF(Monde!L9="","",Monde!L9) | P9: =IF(Monde!M9="","",Monde!M9) | Q9: =IF(Monde!N9="","",Monde!N9) | R9: =IF(Monde!P9="","",Monde!P9) | S9: =IF(Monde!Q9="","",Monde!Q9) | T9: =IF(Monde!R9="","",Monde!R9)
A10: 2000-08 | D10: =IF(Monde!B10="","",Monde!B10) | E10: =IF(Monde!H10="","",Monde!H10) | F10: =IF(Monde!O10="","",Monde!O10) | G10: =IF(Monde!C10="","",Monde!C10) | H10: =IF(Monde!D10="","",Monde!D10) | I10: =IF(Monde!E10="","",Monde!E10) | J10: =IF(Monde!F10="","",Monde!F10) | K10: =IF(Monde!G10="","",Monde!G10) | L10: =IF(Monde!I10="","",Monde!I10) | M10: =IF(Monde!J10="","",Monde!J10) | N10: =IF(Monde!K10="","",Monde!K10) | O10: =IF(Monde!L10="","",Monde!L10) | P10: =IF(Monde!M10="","",Monde!M10) | Q10: =IF(Monde!N10="","",Monde!N10) | R10: =IF(Monde!P10="","",Monde!P10) | S10: =IF(Monde!Q10="","",Monde!Q10) | T10: =IF(Monde!R10="","",Monde!R10)
A11: 2000-09 | D11: =IF(Monde!B11="","",Monde!B11) | E11: =IF(Monde!H11="","",Monde!H11) | F11: =IF(Monde!O11="","",Monde!O11) | G11: =IF(Monde!C11="","",Monde!C11) | H11: =IF(Monde!D11="","",Monde!D11) | I11: =IF(Monde!E11="","",Monde!E11) | J11: =IF(Monde!F11="","",Monde!F11) | K11: =IF(Monde!G11="","",Monde!G11) | L11: =IF(Monde!I11="","",Monde!I11) | M11: =IF(Monde!J11="","",Monde!J11) | N11: =IF(Monde!K11="","",Monde!K11) | O11: =IF(Monde!L11="","",Monde!L11) | P11: =IF(Monde!M11="","",Monde!M11) | Q11: =IF(Monde!N11="","",Monde!N11) | R11: =IF(Monde!P11="","",Monde!P11) | S11: =IF(Monde!Q11="","",Monde!Q11) | T11: =IF(Monde!R11="","",Monde!R11)
A12: 2000-10 | D12: =IF(Monde!B12="","",Monde!B12) | E12: =IF(Monde!H12="","",Monde!H12) | F12: =IF(Monde!O12="","",Monde!O12) | G12: =IF(Monde!C12="","",Monde!C12) | H12: =IF(Monde!D12="","",Monde!D12) | I12: =IF(Monde!E12="","",Monde!E12) | J12: =IF(Monde!F12="","",Monde!F12) | K12: =IF(Monde!G12="","",Monde!G12) | L12: =IF(Monde!I12="","",Monde!I12) | M12: =IF(Monde!J12="","",Monde!J12) | N12: =IF(Monde!K12="","",Monde!K12) | O12: =IF(Monde!L12="","",Monde!L12) | P12: =IF(Monde!M12="","",Monde!M12) | Q12: =IF(Monde!N12="","",Monde!N12) | R12: =IF(Monde!P12="","",Monde!P12) | S12: =IF(Monde!Q12="","",Monde!Q12) | T12: =IF(Monde!R12="","",Monde!R12)
A13: 2000-11 | D13: =IF(Monde!B13="","",Monde!B13) | E13: =IF(Monde!H13="","",Monde!H13) | F13: =IF(Monde!O13="","",Monde!O13) | G13: =IF(Monde!C13="","",Monde!C13) | H13: =IF(Monde!D13="","",Monde!D13) | I13: =IF(Monde!E13="","",Monde!E13) | J13: =IF(Monde!F13="","",Monde!F13) | K13: =IF(Monde!G13="","",Monde!G13) | L13: =IF(Monde!I13="","",Monde!I13) | M13: =IF(Monde!J13="","",Monde!J13) | N13: =IF(Monde!K13="","",Monde!K13) | O13: =IF(Monde!L13="","",Monde!L13) | P13: =IF(Monde!M13="","",Monde!M13) | Q13: =IF(Monde!N13="","",Monde!N13) | R13: =IF(Monde!P13="","",Monde!P13) | S13: =IF(Monde!Q13="","",Monde!Q13) | T13: =IF(Monde!R13="","",Monde!R13)
A14: 2000-12 | D14: =IF(Monde!B14="","",Monde!B14) | E14: =IF(Monde!H14="","",Monde!H14) | F14: =IF(Monde!O14="","",Monde!O14) | G14: =IF(Monde!C14="","",Monde!C14) | H14: =IF(Monde!D14="","",Monde!D14) | I14: =IF(Monde!E14="","",Monde!E14) | J14: =IF(Monde!F14="","",Monde!F14) | K14: =IF(Monde!G14="","",Monde!G14) | L14: =IF(Monde!I14="","",Monde!I14) | M14: =IF(Monde!J14="","",Monde!J14) | N14: =IF(Monde!K14="","",Monde!K14) | O14: =IF(Monde!L14="","",Monde!L14) | P14: =IF(Monde!M14="","",Monde!M14) | Q14: =IF(Monde!N14="","",Monde!N14) | R14: =IF(Monde!P14="","",Monde!P14) | S14: =IF(Monde!Q14="","",Monde!Q14) | T14: =IF(Monde!R14="","",Monde!R14)
... A323: 2026-09 | D323: =IF(Monde!B323="","",Monde!B323) | E323: =IF(Monde!H323="","",Monde!H323) | F323: =IF(Monde!O323="","",Monde!O323) | G323: =IF(Monde!C323="","",Monde!C323) | H323: =IF(Monde!D323="","",Monde!D323) | I323: =IF(Monde!E323="","",Monde!E323) | J323: =IF(Monde!F323="","",Monde!F323) | K323: =IF(Monde!G323="","",Monde!G323) | L323: =IF(Monde!I323="","",Monde!I323) | M323: =IF(Monde!J323="","",Monde!J323) | N323: =IF(Monde!K323="","",Monde!K323) | O323: =IF(Monde!L323="","",Monde!L323) | P323: =IF(Monde!M323="","",Monde!M323) | Q323: =IF(Monde!N323="","",Monde!N323) | R323: =IF(Monde!P323="","",Monde!P323) | S323: =IF(Monde!Q323="","",Monde!Q323) | T323: =IF(Monde!R323="","",Monde!R323)

Sheet GNB
A2: Date | B2: cpi_all | C2: cpi_food | D2: fao_food | E2: oil_usd | F2: usd_xof | G2: fao_cereals | H2: fao_oils | I2: fao_sugar | J2: fao_dairy | K2: fao_meat | L2: rice_thai | M2: wheat_hrw | N2: palm_oil | O2: sugar_world | P2: maize | Q2: eur_usd | R2: gscpi | S2: bceao_import_food | T2: import_food_idx | U2: cpi_all_alt | V2: cpi_food_alt | W2: rain_anom | X2: quality_flag | Y2: note
A3: 2000-01 | D3: =IF(Monde!B3="","",Monde!B3) | E3: =IF(Monde!H3="","",Monde!H3) | F3: =IF(Monde!O3="","",Monde!O3) | G3: =IF(Monde!C3="","",Monde!C3) | H3: =IF(Monde!D3="","",Monde!D3) | I3: =IF(Monde!E3="","",Monde!E3) | J3: =IF(Monde!F3="","",Monde!F3) | K3: =IF(Monde!G3="","",Monde!G3) | L3: =IF(Monde!I3="","",Monde!I3) | M3: =IF(Monde!J3="","",Monde!J3) | N3: =IF(Monde!K3="","",Monde!K3) | O3: =IF(Monde!L3="","",Monde!L3) | P3: =IF(Monde!M3="","",Monde!M3) | Q3: =IF(Monde!N3="","",Monde!N3) | R3: =IF(Monde!P3="","",Monde!P3) | S3: =IF(Monde!Q3="","",Monde!Q3) | T3: =IF(Monde!R3="","",Monde!R3)
A4: 2000-02 | D4: =IF(Monde!B4="","",Monde!B4) | E4: =IF(Monde!H4="","",Monde!H4) | F4: =IF(Monde!O4="","",Monde!O4) | G4: =IF(Monde!C4="","",Monde!C4) | H4: =IF(Monde!D4="","",Monde!D4) | I4: =IF(Monde!E4="","",Monde!E4) | J4: =IF(Monde!F4="","",Monde!F4) | K4: =IF(Monde!G4="","",Monde!G4) | L4: =IF(Monde!I4="","",Monde!I4) | M4: =IF(Monde!J4="","",Monde!J4) | N4: =IF(Monde!K4="","",Monde!K4) | O4: =IF(Monde!L4="","",Monde!L4) | P4: =IF(Monde!M4="","",Monde!M4) | Q4: =IF(Monde!N4="","",Monde!N4) | R4: =IF(Monde!P4="","",Monde!P4) | S4: =IF(Monde!Q4="","",Monde!Q4) | T4: =IF(Monde!R4="","",Monde!R4)
A5: 2000-03 | D5: =IF(Monde!B5="","",Monde!B5) | E5: =IF(Monde!H5="","",Monde!H5) | F5: =IF(Monde!O5="","",Monde!O5) | G5: =IF(Monde!C5="","",Monde!C5) | H5: =IF(Monde!D5="","",Monde!D5) | I5: =IF(Monde!E5="","",Monde!E5) | J5: =IF(Monde!F5="","",Monde!F5) | K5: =IF(Monde!G5="","",Monde!G5) | L5: =IF(Monde!I5="","",Monde!I5) | M5: =IF(Monde!J5="","",Monde!J5) | N5: =IF(Monde!K5="","",Monde!K5) | O5: =IF(Monde!L5="","",Monde!L5) | P5: =IF(Monde!M5="","",Monde!M5) | Q5: =IF(Monde!N5="","",Monde!N5) | R5: =IF(Monde!P5="","",Monde!P5) | S5: =IF(Monde!Q5="","",Monde!Q5) | T5: =IF(Monde!R5="","",Monde!R5)
A6: 2000-04 | D6: =IF(Monde!B6="","",Monde!B6) | E6: =IF(Monde!H6="","",Monde!H6) | F6: =IF(Monde!O6="","",Monde!O6) | G6: =IF(Monde!C6="","",Monde!C6) | H6: =IF(Monde!D6="","",Monde!D6) | I6: =IF(Monde!E6="","",Monde!E6) | J6: =IF(Monde!F6="","",Monde!F6) | K6: =IF(Monde!G6="","",Monde!G6) | L6: =IF(Monde!I6="","",Monde!I6) | M6: =IF(Monde!J6="","",Monde!J6) | N6: =IF(Monde!K6="","",Monde!K6) | O6: =IF(Monde!L6="","",Monde!L6) | P6: =IF(Monde!M6="","",Monde!M6) | Q6: =IF(Monde!N6="","",Monde!N6) | R6: =IF(Monde!P6="","",Monde!P6) | S6: =IF(Monde!Q6="","",Monde!Q6) | T6: =IF(Monde!R6="","",Monde!R6)
A7: 2000-05 | D7: =IF(Monde!B7="","",Monde!B7) | E7: =IF(Monde!H7="","",Monde!H7) | F7: =IF(Monde!O7="","",Monde!O7) | G7: =IF(Monde!C7="","",Monde!C7) | H7: =IF(Monde!D7="","",Monde!D7) | I7: =IF(Monde!E7="","",Monde!E7) | J7: =IF(Monde!F7="","",Monde!F7) | K7: =IF(Monde!G7="","",Monde!G7) | L7: =IF(Monde!I7="","",Monde!I7) | M7: =IF(Monde!J7="","",Monde!J7) | N7: =IF(Monde!K7="","",Monde!K7) | O7: =IF(Monde!L7="","",Monde!L7) | P7: =IF(Monde!M7="","",Monde!M7) | Q7: =IF(Monde!N7="","",Monde!N7) | R7: =IF(Monde!P7="","",Monde!P7) | S7: =IF(Monde!Q7="","",Monde!Q7) | T7: =IF(Monde!R7="","",Monde!R7)
A8: 2000-06 | D8: =IF(Monde!B8="","",Monde!B8) | E8: =IF(Monde!H8="","",Monde!H8) | F8: =IF(Monde!O8="","",Monde!O8) | G8: =IF(Monde!C8="","",Monde!C8) | H8: =IF(Monde!D8="","",Monde!D8) | I8: =IF(Monde!E8="","",Monde!E8) | J8: =IF(Monde!F8="","",Monde!F8) | K8: =IF(Monde!G8="","",Monde!G8) | L8: =IF(Monde!I8="","",Monde!I8) | M8: =IF(Monde!J8="","",Monde!J8) | N8: =IF(Monde!K8="","",Monde!K8) | O8: =IF(Monde!L8="","",Monde!L8) | P8: =IF(Monde!M8="","",Monde!M8) | Q8: =IF(Monde!N8="","",Monde!N8) | R8: =IF(Monde!P8="","",Monde!P8) | S8: =IF(Monde!Q8="","",Monde!Q8) | T8: =IF(Monde!R8="","",Monde!R8)
A9: 2000-07 | D9: =IF(Monde!B9="","",Monde!B9) | E9: =IF(Monde!H9="","",Monde!H9) | F9: =IF(Monde!O9="","",Monde!O9) | G9: =IF(Monde!C9="","",Monde!C9) | H9: =IF(Monde!D9="","",Monde!D9) | I9: =IF(Monde!E9="","",Monde!E9) | J9: =IF(Monde!F9="","",Monde!F9) | K9: =IF(Monde!G9="","",Monde!G9) | L9: =IF(Monde!I9="","",Monde!I9) | M9: =IF(Monde!J9="","",Monde!J9) | N9: =IF(Monde!K9="","",Monde!K9) | O9: =IF(Monde!L9="","",Monde!L9) | P9: =IF(Monde!M9="","",Monde!M9) | Q9: =IF(Monde!N9="","",Monde!N9) | R9: =IF(Monde!P9="","",Monde!P9) | S9: =IF(Monde!Q9="","",Monde!Q9) | T9: =IF(Monde!R9="","",Monde!R9)
A10: 2000-08 | D10: =IF(Monde!B10="","",Monde!B10) | E10: =IF(Monde!H10="","",Monde!H10) | F10: =IF(Monde!O10="","",Monde!O10) | G10: =IF(Monde!C10="","",Monde!C10) | H10: =IF(Monde!D10="","",Monde!D10) | I10: =IF(Monde!E10="","",Monde!E10) | J10: =IF(Monde!F10="","",Monde!F10) | K10: =IF(Monde!G10="","",Monde!G10) | L10: =IF(Monde!I10="","",Monde!I10) | M10: =IF(Monde!J10="","",Monde!J10) | N10: =IF(Monde!K10="","",Monde!K10) | O10: =IF(Monde!L10="","",Monde!L10) | P10: =IF(Monde!M10="","",Monde!M10) | Q10: =IF(Monde!N10="","",Monde!N10) | R10: =IF(Monde!P10="","",Monde!P10) | S10: =IF(Monde!Q10="","",Monde!Q10) | T10: =IF(Monde!R10="","",Monde!R10)
A11: 2000-09 | D11: =IF(Monde!B11="","",Monde!B11) | E11: =IF(Monde!H11="","",Monde!H11) | F11: =IF(Monde!O11="","",Monde!O11) | G11: =IF(Monde!C11="","",Monde!C11) | H11: =IF(Monde!D11="","",Monde!D11) | I11: =IF(Monde!E11="","",Monde!E11) | J11: =IF(Monde!F11="","",Monde!F11) | K11: =IF(Monde!G11="","",Monde!G11) | L11: =IF(Monde!I11="","",Monde!I11) | M11: =IF(Monde!J11="","",Monde!J11) | N11: =IF(Monde!K11="","",Monde!K11) | O11: =IF(Monde!L11="","",Monde!L11) | P11: =IF(Monde!M11="","",Monde!M11) | Q11: =IF(Monde!N11="","",Monde!N11) | R11: =IF(Monde!P11="","",Monde!P11) | S11: =IF(Monde!Q11="","",Monde!Q11) | T11: =IF(Monde!R11="","",Monde!R11)
A12: 2000-10 | D12: =IF(Monde!B12="","",Monde!B12) | E12: =IF(Monde!H12="","",Monde!H12) | F12: =IF(Monde!O12="","",Monde!O12) | G12: =IF(Monde!C12="","",Monde!C12) | H12: =IF(Monde!D12="","",Monde!D12) | I12: =IF(Monde!E12="","",Monde!E12) | J12: =IF(Monde!F12="","",Monde!F12) | K12: =IF(Monde!G12="","",Monde!G12) | L12: =IF(Monde!I12="","",Monde!I12) | M12: =IF(Monde!J12="","",Monde!J12) | N12: =IF(Monde!K12="","",Monde!K12) | O12: =IF(Monde!L12="","",Monde!L12) | P12: =IF(Monde!M12="","",Monde!M12) | Q12: =IF(Monde!N12="","",Monde!N12) | R12: =IF(Monde!P12="","",Monde!P12) | S12: =IF(Monde!Q12="","",Monde!Q12) | T12: =IF(Monde!R12="","",Monde!R12)
A13: 2000-11 | D13: =IF(Monde!B13="","",Monde!B13) | E13: =IF(Monde!H13="","",Monde!H13) | F13: =IF(Monde!O13="","",Monde!O13) | G13: =IF(Monde!C13="","",Monde!C13) | H13: =IF(Monde!D13="","",Monde!D13) | I13: =IF(Monde!E13="","",Monde!E13) | J13: =IF(Monde!F13="","",Monde!F13) | K13: =IF(Monde!G13="","",Monde!G13) | L13: =IF(Monde!I13="","",Monde!I13) | M13: =IF(Monde!J13="","",Monde!J13) | N13: =IF(Monde!K13="","",Monde!K13) | O13: =IF(Monde!L13="","",Monde!L13) | P13: =IF(Monde!M13="","",Monde!M13) | Q13: =IF(Monde!N13="","",Monde!N13) | R13: =IF(Monde!P13="","",Monde!P13) | S13: =IF(Monde!Q13="","",Monde!Q13) | T13: =IF(Monde!R13="","",Monde!R13)
A14: 2000-12 | D14: =IF(Monde!B14="","",Monde!B14) | E14: =IF(Monde!H14="","",Monde!H14) | F14: =IF(Monde!O14="","",Monde!O14) | G14: =IF(Monde!C14="","",Monde!C14) | H14: =IF(Monde!D14="","",Monde!D14) | I14: =IF(Monde!E14="","",Monde!E14) | J14: =IF(Monde!F14="","",Monde!F14) | K14: =IF(Monde!G14="","",Monde!G14) | L14: =IF(Monde!I14="","",Monde!I14) | M14: =IF(Monde!J14="","",Monde!J14) | N14: =IF(Monde!K14="","",Monde!K14) | O14: =IF(Monde!L14="","",Monde!L14) | P14: =IF(Monde!M14="","",Monde!M14) | Q14: =IF(Monde!N14="","",Monde!N14) | R14: =IF(Monde!P14="","",Monde!P14) | S14: =IF(Monde!Q14="","",Monde!Q14) | T14: =IF(Monde!R14="","",Monde!R14)
... A323: 2026-09 | D323: =IF(Monde!B323="","",Monde!B323) | E323: =IF(Monde!H323="","",Monde!H323) | F323: =IF(Monde!O323="","",Monde!O323) | G323: =IF(Monde!C323="","",Monde!C323) | H323: =IF(Monde!D323="","",Monde!D323) | I323: =IF(Monde!E323="","",Monde!E323) | J323: =IF(Monde!F323="","",Monde!F323) | K323: =IF(Monde!G323="","",Monde!G323) | L323: =IF(Monde!I323="","",Monde!I323) | M323: =IF(Monde!J323="","",Monde!J323) | N323: =IF(Monde!K323="","",Monde!K323) | O323: =IF(Monde!L323="","",Monde!L323) | P323: =IF(Monde!M323="","",Monde!M323) | Q323: =IF(Monde!N323="","",Monde!N323) | R323: =IF(Monde!P323="","",Monde!P323) | S323: =IF(Monde!Q323="","",Monde!Q323) | T323: =IF(Monde!R323="","",Monde!R323)

Sheet MLI
A2: Date | B2: cpi_all | C2: cpi_food | D2: fao_food | E2: oil_usd | F2: usd_xof | G2: fao_cereals | H2: fao_oils | I2: fao_sugar | J2: fao_dairy | K2: fao_meat | L2: rice_thai | M2: wheat_hrw | N2: palm_oil | O2: sugar_world | P2: maize | Q2: eur_usd | R2: gscpi | S2: bceao_import_food | T2: import_food_idx | U2: cpi_all_alt | V2: cpi_food_alt | W2: rain_anom | X2: quality_flag | Y2: note
A3: 2000-01 | D3: =IF(Monde!B3="","",Monde!B3) | E3: =IF(Monde!H3="","",Monde!H3) | F3: =IF(Monde!O3="","",Monde!O3) | G3: =IF(Monde!C3="","",Monde!C3) | H3: =IF(Monde!D3="","",Monde!D3) | I3: =IF(Monde!E3="","",Monde!E3) | J3: =IF(Monde!F3="","",Monde!F3) | K3: =IF(Monde!G3="","",Monde!G3) | L3: =IF(Monde!I3="","",Monde!I3) | M3: =IF(Monde!J3="","",Monde!J3) | N3: =IF(Monde!K3="","",Monde!K3) | O3: =IF(Monde!L3="","",Monde!L3) | P3: =IF(Monde!M3="","",Monde!M3) | Q3: =IF(Monde!N3="","",Monde!N3) | R3: =IF(Monde!P3="","",Monde!P3) | S3: =IF(Monde!Q3="","",Monde!Q3) | T3: =IF(Monde!R3="","",Monde!R3)
A4: 2000-02 | D4: =IF(Monde!B4="","",Monde!B4) | E4: =IF(Monde!H4="","",Monde!H4) | F4: =IF(Monde!O4="","",Monde!O4) | G4: =IF(Monde!C4="","",Monde!C4) | H4: =IF(Monde!D4="","",Monde!D4) | I4: =IF(Monde!E4="","",Monde!E4) | J4: =IF(Monde!F4="","",Monde!F4) | K4: =IF(Monde!G4="","",Monde!G4) | L4: =IF(Monde!I4="","",Monde!I4) | M4: =IF(Monde!J4="","",Monde!J4) | N4: =IF(Monde!K4="","",Monde!K4) | O4: =IF(Monde!L4="","",Monde!L4) | P4: =IF(Monde!M4="","",Monde!M4) | Q4: =IF(Monde!N4="","",Monde!N4) | R4: =IF(Monde!P4="","",Monde!P4) | S4: =IF(Monde!Q4="","",Monde!Q4) | T4: =IF(Monde!R4="","",Monde!R4)
A5: 2000-03 | D5: =IF(Monde!B5="","",Monde!B5) | E5: =IF(Monde!H5="","",Monde!H5) | F5: =IF(Monde!O5="","",Monde!O5) | G5: =IF(Monde!C5="","",Monde!C5) | H5: =IF(Monde!D5="","",Monde!D5) | I5: =IF(Monde!E5="","",Monde!E5) | J5: =IF(Monde!F5="","",Monde!F5) | K5: =IF(Monde!G5="","",Monde!G5) | L5: =IF(Monde!I5="","",Monde!I5) | M5: =IF(Monde!J5="","",Monde!J5) | N5: =IF(Monde!K5="","",Monde!K5) | O5: =IF(Monde!L5="","",Monde!L5) | P5: =IF(Monde!M5="","",Monde!M5) | Q5: =IF(Monde!N5="","",Monde!N5) | R5: =IF(Monde!P5="","",Monde!P5) | S5: =IF(Monde!Q5="","",Monde!Q5) | T5: =IF(Monde!R5="","",Monde!R5)
A6: 2000-04 | D6: =IF(Monde!B6="","",Monde!B6) | E6: =IF(Monde!H6="","",Monde!H6) | F6: =IF(Monde!O6="","",Monde!O6) | G6: =IF(Monde!C6="","",Monde!C6) | H6: =IF(Monde!D6="","",Monde!D6) | I6: =IF(Monde!E6="","",Monde!E6) | J6: =IF(Monde!F6="","",Monde!F6) | K6: =IF(Monde!G6="","",Monde!G6) | L6: =IF(Monde!I6="","",Monde!I6) | M6: =IF(Monde!J6="","",Monde!J6) | N6: =IF(Monde!K6="","",Monde!K6) | O6: =IF(Monde!L6="","",Monde!L6) | P6: =IF(Monde!M6="","",Monde!M6) | Q6: =IF(Monde!N6="","",Monde!N6) | R6: =IF(Monde!P6="","",Monde!P6) | S6: =IF(Monde!Q6="","",Monde!Q6) | T6: =IF(Monde!R6="","",Monde!R6)
A7: 2000-05 | D7: =IF(Monde!B7="","",Monde!B7) | E7: =IF(Monde!H7="","",Monde!H7) | F7: =IF(Monde!O7="","",Monde!O7) | G7: =IF(Monde!C7="","",Monde!C7) | H7: =IF(Monde!D7="","",Monde!D7) | I7: =IF(Monde!E7="","",Monde!E7) | J7: =IF(Monde!F7="","",Monde!F7) | K7: =IF(Monde!G7="","",Monde!G7) | L7: =IF(Monde!I7="","",Monde!I7) | M7: =IF(Monde!J7="","",Monde!J7) | N7: =IF(Monde!K7="","",Monde!K7) | O7: =IF(Monde!L7="","",Monde!L7) | P7: =IF(Monde!M7="","",Monde!M7) | Q7: =IF(Monde!N7="","",Monde!N7) | R7: =IF(Monde!P7="","",Monde!P7) | S7: =IF(Monde!Q7="","",Monde!Q7) | T7: =IF(Monde!R7="","",Monde!R7)
A8: 2000-06 | D8: =IF(Monde!B8="","",Monde!B8) | E8: =IF(Monde!H8="","",Monde!H8) | F8: =IF(Monde!O8="","",Monde!O8) | G8: =IF(Monde!C8="","",Monde!C8) | H8: =IF(Monde!D8="","",Monde!D8) | I8: =IF(Monde!E8="","",Monde!E8) | J8: =IF(Monde!F8="","",Monde!F8) | K8: =IF(Monde!G8="","",Monde!G8) | L8: =IF(Monde!I8="","",Monde!I8) | M8: =IF(Monde!J8="","",Monde!J8) | N8: =IF(Monde!K8="","",Monde!K8) | O8: =IF(Monde!L8="","",Monde!L8) | P8: =IF(Monde!M8="","",Monde!M8) | Q8: =IF(Monde!N8="","",Monde!N8) | R8: =IF(Monde!P8="","",Monde!P8) | S8: =IF(Monde!Q8="","",Monde!Q8) | T8: =IF(Monde!R8="","",Monde!R8)
